[2025-07-28T12:07:11.706+0000] {taskinstance.py:1159} INFO - Dependencies all met for dep_context=non-requeueable deps ti=<TaskInstance: show_recent_logs.show_recent_logs manual__2025-07-28T12:07:09.962877+00:00 [queued]>
[2025-07-28T12:07:11.712+0000] {taskinstance.py:1159} INFO - Dependencies all met for dep_context=requeueable deps ti=<TaskInstance: show_recent_logs.show_recent_logs manual__2025-07-28T12:07:09.962877+00:00 [queued]>
[2025-07-28T12:07:11.712+0000] {taskinstance.py:1361} INFO - Starting attempt 1 of 1
[2025-07-28T12:07:11.721+0000] {taskinstance.py:1382} INFO - Executing <Task(PythonOperator): show_recent_logs> on 2025-07-28 12:07:09.962877+00:00
[2025-07-28T12:07:11.726+0000] {standard_task_runner.py:57} INFO - Started process 1699 to run task
[2025-07-28T12:07:11.728+0000] {standard_task_runner.py:84} INFO - Running: ['airflow', 'tasks', 'run', 'show_recent_logs', 'show_recent_logs', 'manual__2025-07-28T12:07:09.962877+00:00', '--job-id', '14', '--raw', '--subdir', 'DAGS_FOLDER/log_reader_dag.py', '--cfg-path', '/tmp/tmpbk4vol5q']
[2025-07-28T12:07:11.729+0000] {standard_task_runner.py:85} INFO - Job 14: Subtask show_recent_logs
[2025-07-28T12:07:11.773+0000] {task_command.py:415} INFO - Running <TaskInstance: show_recent_logs.show_recent_logs manual__2025-07-28T12:07:09.962877+00:00 [running]> on host 00b4b9fb4b52
[2025-07-28T12:07:11.838+0000] {taskinstance.py:1660} INFO - Exporting env vars: AIRFLOW_CTX_DAG_OWNER='airflow' AIRFLOW_CTX_DAG_ID='show_recent_logs' AIRFLOW_CTX_TASK_ID='show_recent_logs' AIRFLOW_CTX_EXECUTION_DATE='2025-07-28T12:07:09.962877+00:00' AIRFLOW_CTX_TRY_NUMBER='1' AIRFLOW_CTX_DAG_RUN_ID='manual__2025-07-28T12:07:09.962877+00:00'
[2025-07-28T12:07:11.844+0000] {taskinstance.py:1943} ERROR - Task failed with exception
Traceback (most recent call last):
  File "/home/airflow/.local/lib/python3.8/site-packages/airflow/operators/python.py", line 192, in execute
    return_value = self.execute_callable()
  File "/home/airflow/.local/lib/python3.8/site-packages/airflow/operators/python.py", line 209, in execute_callable
    return self.python_callable(*self.op_args, **self.op_kwargs)
  File "/opt/airflow/dags/log_reader_dag.py", line 13, in print_recent_logs
    cursor.execute("SELECT * FROM logs LIMIT 10;")
psycopg2.errors.UndefinedTable: relation "logs" does not exist
LINE 1: SELECT * FROM logs LIMIT 10;
                      ^

[2025-07-28T12:07:11.853+0000] {taskinstance.py:1400} INFO - Marking task as FAILED. dag_id=show_recent_logs, task_id=show_recent_logs, execution_date=20250728T120709, start_date=20250728T120711, end_date=20250728T120711
[2025-07-28T12:07:11.861+0000] {standard_task_runner.py:104} ERROR - Failed to execute job 14 for task show_recent_logs (relation "logs" does not exist
LINE 1: SELECT * FROM logs LIMIT 10;
                      ^
; 1699)
[2025-07-28T12:07:11.900+0000] {local_task_job_runner.py:228} INFO - Task exited with return code 1
[2025-07-28T12:07:11.915+0000] {taskinstance.py:2784} INFO - 0 downstream tasks scheduled from follow-on schedule check
